Workbook

Sheet TECHM
V1: DATA FROM NSE
F2: HISTORICAL DATA TECH MAHINDRA
A4: # | B4: DATE | C4: SERIES | D4: OPEN | E4: HIGH | F4: LOW | G4: PREV. CLOSE | H4: LTP | I4: CLOSE | J4: VWAP | K4: 52 WEEK HIGH | L4: 52 WEEK LOW | M4: VOLUME | N4: VALUE | O4: NO. OF TRADES | Q4: DAILY % RETURNS | R4: Standard Deviation | S4: Average of DR | T4: Cumulative Returns | U4: Beta Coefficient
B5: 46276 | C5: EQ | D5: 1519.3 | E5: 1557.3 | F5: 1518.6 | G5: 1525.8 | H5: 1541 | I5: 1541 | J5: 1543.63 | K5: 1854 | L5: 1304.1 | M5: 20,07,328 | N5: 3,09,85,74,254.10 | O5: 68622 | Q5: 0
B6: 46275 | C6: EQ | D6: 1511.9 | E6: 1544.7 | F6: 1498.1 | G6: 1508 | H6: 1525.8 | I6: 1525.8 | J6: 1526.06 | K6: 1854 | L6: 1304.1 | M6: 14,05,653 | N6: 2,14,51,15,219.70 | O6: 50917 | Q6: =(I6/I5)-1 -> -0.0098637249 | U6: sep
B7: 46274 | C7: EQ | D7: 1531 | E7: 1531 | F7: 1498 | G7: 1559 | H7: 1508 | I7: 1508 | J7: 1508.2 | K7: 1854 | L7: 1304.1 | M7: 13,29,200 | N7: 2,00,46,99,140.80 | O7: 65093 | Q7: =(I7/I6)-1 -> -0.011666011 | R7: =_xlfn.STDEV.S($Q$5:$Q$19) -> 0.016644223 | S7: =AVERAGE($Q$5:$Q$19) -> 0.0019657047 | T7: =($I$19-$I$5)/$I$5 -> 0.027903958 | U7: =SLOPE($Q$6:$Q$19,$R$31:$R$44) -> -0.81398852
B8: 46273 | C8: EQ | D8: 1556.1 | E8: 1569.9 | F8: 1541.4 | G8: 1564 | H8: 1559 | I8: 1559 | J8: 1553.5 | K8: 1854 | L8: 1304.1 | M8: 15,75,629 | N8: 2,44,77,37,503.10 | O8: 68913 | Q8: =(I8/I7)-1 -> 0.033819629
B9: 46272 | C9: EQ | D9: 1575.1 | E9: 1593.6 | F9: 1545.3 | G9: 1596.9 | H9: 1564 | I9: 1564 | J9: 1558.67 | K9: 1854 | L9: 1304.1 | M9: 20,28,588 | N9: 3,16,19,05,917.50 | O9: 50380 | Q9: =(I9/I8)-1 -> 0.0032071841 | R9: =_xlfn.STDEV.S($Q$5:$Q$19) -> 0.016644223 | S9: =AVERAGE($Q$5:$Q$19) -> 0.0019657047 | T9: =($I$19-$I$5)/$I$5 -> 0.027903958 | U9: =SLOPE($Q$6:$Q$19,$R$31:$R$44) -> -0.81398852
B10: 46269 | C10: EQ | D10: 1605.1 | E10: 1623.4 | F10: 1586.9 | G10: 1598 | H10: 1596.9 | I10: 1596.9 | J10: 1597.39 | K10: 1854 | L10: 1304.1 | M10: 11,73,518 | N10: 1,87,45,70,781.10 | O10: 27058 | Q10: =(I10/I9)-1 -> 0.021035806 | U10: oct
B11: 46268 | C11: EQ | D11: 1623 | E11: 1625.6 | F11: 1592 | G11: 1623 | H11: 1598 | I11: 1598 | J11: 1600.2 | K11: 1854 | L11: 1304.1 | M11: 16,47,483 | N11: 2,63,63,09,499.20 | O11: 57407 | Q11: =(I11/I10)-1 -> 0.00068883462 | U11: =SLOPE($Q$6:$Q$19,$R$48:$R$61) -> -0.86159421
B12: 46267 | C12: EQ | D12: 1630 | E12: 1637.2 | F12: 1604.5 | G12: 1638 | H12: 1623 | I12: 1623 | J12: 1616.74 | K12: 1854 | L12: 1304.1 | M12: 15,08,528 | N12: 2,43,88,97,122.60 | O12: 69222 | Q12: =(I12/I11)-1 -> 0.015644556 | U12: =SLOPE($Q$6:$Q$19,$R$48:$R$61) -> -0.86159421
B13: 46266 | C13: EQ | D13: 1630 | E13: 1649 | F13: 1613.7 | G13: 1628 | H13: 1638 | I13: 1638 | J13: 1637.05 | K13: 1854 | L13: 1304.1 | M13: 24,12,137 | N13: 3,94,87,81,374.30 | O13: 76425 | Q13: =(I13/I12)-1 -> 0.0092421442 | U13: nov
B14: 46265 | C14: EQ | D14: 1640 | E14: 1640.9 | F14: 1609.1 | G14: 1640.9 | H14: 1628 | I14: 1628 | J14: 1623.29 | K14: 1854 | L14: 1304.1 | M14: 29,75,369 | N14: 4,82,98,94,367.30 | O14: 68160 | Q14: =(I14/I13)-1 -> -0.0061050061 | U14: =SLOPE($Q$8:$Q$19,$R$66:$R$77) -> -0.32821134
B15: 46262 | C15: EQ | D15: 1600 | E15: 1642 | F15: 1598 | G15: 1585 | H15: 1640.9 | I15: 1640.9 | J15: 1631.09 | K15: 1854 | L15: 1304.1 | M15: 34,15,226 | N15: 5,57,05,51,817.60 | O15: 94086 | Q15: =(I15/I14)-1 -> 0.0079238329 | U15: =SLOPE($Q$8:$Q$19,$R$66:$R$77) -> -0.32821134
B16: 46261 | C16: EQ | D16: 1571.6 | E16: 1600 | F16: 1571.6 | G16: 1571 | H16: 1585 | I16: 1585 | J16: 1588.85 | K16: 1854 | L16: 1304.1 | M16: 19,79,336 | N16: 3,14,48,64,224.20 | O16: 78804 | Q16: =(I16/I15)-1 -> -0.034066671
B17: 46260 | C17: EQ | D17: 1607.5 | E17: 1614.9 | F17: 1565.8 | G17: 1599.9 | H17: 1571 | I17: 1571 | J17: 1579.52 | K17: 1854 | L17: 1304.1 | M17: 16,39,820 | N17: 2,59,01,21,633.80 | O17: 33321 | Q17: =(I17/I16)-1 -> -0.0088328076
B18: 46259 | C18: EQ | D18: 1588.1 | E18: 1599.9 | F18: 1562 | G18: 1584 | H18: 1599.9 | I18: 1599.9 | J18: 1575.62 | K18: 1854 | L18: 1304.1 | M18: 13,83,429 | N18: 2,17,97,61,125.50 | O18: 49801 | Q18: =(I18/I17)-1 -> 0.018395926
B19: 46258 | C19: EQ | D19: 1580.1 | E19: 1599 | F19: 1574.1 | G19: 1584 | H19: 1584 | I19: 1584 | J19: 1587.42 | K19: 1854 | L19: 1304.1 | M19: 21,97,042 | N19: 3,48,76,26,491.10 | O19: 1,01,243 | Q19: =(I19/I18)-1 -> -0.0099381211
V25: DATA FROM NSE
F26: HISTORICAL DATA NIFTY 50
A28: # | B28: Date | C28: Expiry Date | D28: Open Price | E28: High Price | F28: Low Price | G28: Close Price | H28: Last Price | I28: Volume | K28: Date | L28: Expiry Date | M28: Open Price | N28: High Price | O28: Low Price | P28: Close Price | Q28: Last Price | R28: DAILY % RETURNS | S28: Average of DR | T28: Standard Deviation | U28: Cumulative Returns
B30: 46276 | C30: 46322 | D30: 23466.1 | E30: 23617.6 | F30: 23388.3 | G30: 23586.6 | H30: 23604 | I30: 5,97,350 | K30: 46258 | L30: 46294 | M30: 24475 | N30: 24475 | O30: 24287.1 | P30: 24324.1 | Q30: 24319.1 | R30: =0 -> 0 | S30: =AVERAGE($R$31:$R$44) -> -0.0024956059 | T30: =_xlfn.STDEV.S($R$31:$R$44) -> 0.0041990049 | U30: =($P$44-$P$30)/$P$30 -> -0.034488429
B31: 46276 | C31: 46294 | D31: 23335 | E31: 23517.4 | F31: 23300 | G31: 23485.2 | H31: 23499 | I31: 32,84,450 | K31: 46259 | L31: 46294 | M31: 24320 | N31: 24496 | O31: 24260 | P31: 24471.7 | Q31: 24485.2 | R31: =(P31/P30)-1 -> 0.006068056
B32: 46276 | C32: 46349 | D32: 23568.3 | E32: 23712 | F32: 23493 | G32: 23686 | H32: 23700 | I32: 1,66,920 | K32: 46260 | L32: 46294 | M32: 24540 | N32: 24573.5 | O32: 24405.1 | P32: 24429.1 | Q32: 24420 | R32: =(P32/P31)-1 -> -0.0017407863 | S32: =AVERAGE($R$31:$R$44) -> -0.0024956059 | T32: =_xlfn.STDEV.S($R$31:$R$44) -> 0.0041990049 | U32: =($P$44-$P$30)/$P$30 -> -0.034488429
B33: 46275 | C33: 46322 | D33: 23622.8 | E33: 23668.9 | F33: 23560 | G33: 23584 | H33: 23604 | I33: 4,87,240 | K33: 46261 | L33: 46294 | M33: 24399.5 | N33: 24430 | O33: 24260 | P33: 24281.9 | Q33: 24266 | R33: =(P33/P32)-1 -> -0.0060256006
B34: 46275 | C34: 46349 | D34: 23779.9 | E34: 23779.9 | F34: 23663.5 | G34: 23698.3 | H34: 23700 | I34: 1,09,525 | K34: 46262 | L34: 46294 | M34: 24292.7 | N34: 24380.2 | O34: 24250 | P34: 24341.9 | Q34: 24349 | R34: =(P34/P33)-1 -> 0.0024709763
B35: 46275 | C35: 46294 | D35: 23525.5 | E35: 23569 | F35: 23455.5 | G35: 23484 | H35: 23500.1 | I35: 17,37,775 | K35: 46265 | L35: 46294 | M35: 24244 | N35: 24319 | O35: 24171 | P35: 24251.4 | Q35: 24245 | R35: =(P35/P34)-1 -> -0.0037178692
B36: 46274 | C36: 46322 | D36: 23786 | E36: 23786 | F36: 23629 | G36: 23660.2 | H36: 23629 | I36: 4,85,615 | K36: 46266 | L36: 46294 | M36: 24200 | N36: 24296.1 | O36: 24064 | P36: 24090.3 | Q36: 24081 | R36: =(P36/P35)-1 -> -0.0066429155
B37: 46274 | C37: 46294 | D37: 23674 | E37: 23674 | F37: 23517.1 | G37: 23552.2 | H37: 23530 | I37: 35,97,425 | K37: 46267 | L37: 46294 | M37: 24000 | N37: 24049 | O37: 23940 | P37: 24000.3 | Q37: 23994.8 | R37: =(P37/P36)-1 -> -0.0037359435
B38: 46274 | C38: 46349 | D38: 23944.9 | E38: 23944.9 | F38: 23730 | G38: 23768.6 | H38: 23730 | I38: 2,05,400 | K38: 46268 | L38: 46294 | M38: 24085 | N38: 24148 | O38: 23971.1 | P38: 24000.1 | Q38: 23974.8 | R38: =(P38/P37)-1 -> -8.3332292e-06
B39: 46273 | C39: 46322 | D39: 23971 | E39: 23971 | F39: 23830 | G39: 23850.6 | H39: 23850 | I39: 4,51,425 | K39: 46269 | L39: 46294 | M39: 24041 | N39: 24120 | O39: 24025 | P39: 24048.1 | Q39: 24048 | R39: =(P39/P38)-1 -> 0.0019999917
B40: 46273 | C40: 46349 | D40: 24050 | E40: 24050.1 | F40: 23937 | G40: 23951.6 | H40: 23955 | I40: 1,91,555 | K40: 46272 | L40: 46294 | M40: 24000 | N40: 24000 | O40: 23855 | P40: 23867.7 | Q40: 23866.1 | R40: =(P40/P39)-1 -> -0.0075016321
B41: 46273 | C41: 46294 | D41: 23828 | E41: 23830 | F41: 23725 | G41: 23749.6 | H41: 23744.1 | I41: 21,75,290 | K41: 46273 | L41: 46294 | M41: 23828 | N41: 23830 | O41: 23725 | P41: 23749.6 | Q41: 23744.1 | R41: =(P41/P40)-1 -> -0.0049481098
B42: 46272 | C42: 46349 | D42: 24235.1 | E42: 24235.1 | F42: 24070.3 | G42: 24082.8 | H42: 24079.6 | I42: 1,42,220 | K42: 46274 | L42: 46294 | M42: 23674 | N42: 23674 | O42: 23517.1 | P42: 23552.2 | Q42: 23530 | R42: =(P42/P41)-1 -> -0.0083117189
B43: 46272 | C43: 46294 | D43: 24000 | E43: 24000 | F43: 23855 | G43: 23867.7 | H43: 23866.1 | I43: 23,02,235 | K43: 46275 | L43: 46294 | M43: 23525.5 | N43: 23569 | O43: 23455.5 | P43: 23484 | Q43: 23500.1 | R43: =(P43/P42)-1 -> -0.0028956955
B44: 46272 | C44: 46322 | D44: 24100.2 | E44: 24100.2 | F44: 23960 | G44: 23975.8 | H44: 23971 | I44: 3,48,595 | K44: 46276 | L44: 46294 | M44: 23335 | N44: 23517.4 | O44: 23300 | P44: 23485.2 | Q44: 23499 | R44: =(P44/P43)-1 -> 5.109862e-05
B45: 46269 | C45: 46322 | D45: 24119.4 | E45: 24221.9 | F45: 24119.4 | G45: 24149.4 | H45: 24150 | I45: 1,54,440
B46: 46269 | C46: 46349 | D46: 24300 | E46: 24330 | F46: 24225.9 | G46: 24262 | H46: 24266.7 | I46: 55445
B47: 46269 | C47: 46294 | D47: 24041 | E47: 24120 | F47: 24025 | G47: 24048.1 | H47: 24048 | I47: 18,36,380 | K47: 46258 | L47: 46322 | M47: 24585 | N47: 24585 | O47: 24411 | P47: 24441.9 | Q47: 24428.8
B48: 46268 | C48: 46322 | D48: 24179.4 | E48: 24254.6 | F48: 24078 | G48: 24103.6 | H48: 24079.6 | I48: 2,30,100 | K48: 46259 | L48: 46322 | M48: 24441.9 | N48: 24611.2 | O48: 24376.1 | P48: 24590.4 | Q48: 24611.2 | R48: =(P48/P47)-1 -> 0.0060756324 | S48: =AVERAGE(R48:R61) -> -0.0025328597 | T48: =_xlfn.STDEV.S(R48:R61) -> 0.0041998093 | U48: =(P61-P47)/P47 -> -0.034993188
...

Sheet TCS
Q1: DATA FROM NSE
E2: HISTORICAL DATA TCS
A4: DATE | B4: SERIES | C4: OPEN | D4: HIGH | E4: LOW | F4: PREV. CLOSE | G4: LTP | H4: CLOSE | I4: VWAP | J4: 52 WEEK HIGH | K4: 52 WEEK LOW | L4: VOLUME | M4: VALUE | N4: NO. OF TRADES | P4: DAILY % RETURNS | Q4: Standard Deviation | R4: Average of DR | S4: Cumulative Returns | T4: Beta Coefficient
A5: 46276 | B5: EQ | C5: 2185.5 | D5: 2232.6 | E5: 2185.5 | F5: 2204.1 | G5: 2200.8 | H5: 2200.8 | I5: 2210.94 | J5: 3350 | K5: 1976.8 | L5: 26,34,124 | M5: 5,82,38,96,659.40 | N5: 1,02,069 | P5: 0 | T5: SEP
A6: 46275 | B6: EQ | C6: 2199 | D6: 2232 | E6: 2190.6 | F6: 2208 | G6: 2204.1 | H6: 2204.1 | I6: 2205.28 | J6: 3350 | K6: 1976.8 | L6: 24,90,912 | M6: 5,49,31,46,435.50 | N6: 79204 | P6: =(H6/H5)-1 -> 0.0014994547 | Q6: =_xlfn.STDEV.S(P6:P19) -> 0.01636905 | R6: =AVERAGE(P6:P19) -> 0.0027833391 | S6: =(H19-H5)/H5 -> 0.037849873 | T6: =SLOPE(P6:P19,TECHM!R31:R44) -> 0.57311927
A7: 46274 | B7: EQ | C7: 2237 | D7: 2237 | E7: 2193.2 | F7: 2255.5 | G7: 2208 | H7: 2208 | I7: 2207.41 | J7: 3350 | K7: 1976.8 | L7: 33,70,071 | M7: 7,43,91,43,444.60 | N7: 1,24,491 | P7: =(H7/H6)-1 -> 0.0017694297 | T7: OCT
A8: 46273 | B8: EQ | C8: 2270 | D8: 2274.5 | E8: 2244 | F8: 2270 | G8: 2255.5 | H8: 2255.5 | I8: 2263.52 | J8: 3350 | K8: 1976.8 | L8: 21,48,114 | M8: 4,86,23,08,617.40 | N8: 70112 | P8: =(H8/H7)-1 -> 0.021512681 | T8: =SLOPE(P6:P19,TECHM!R48:R61) -> 0.54228841
A9: 46272 | B9: EQ | C9: 2290.1 | D9: 2299.9 | E9: 2260.1 | F9: 2304 | G9: 2270 | H9: 2270 | I9: 2273.31 | J9: 3350 | K9: 1976.8 | L9: 22,97,551 | M9: 5,22,30,48,792.00 | N9: 70867 | P9: =(H9/H8)-1 -> 0.0064287298 | T9: NOV
A10: 46269 | B10: EQ | C10: 2330 | D10: 2363.9 | E10: 2302.4 | F10: 2320.1 | G10: 2304 | H10: 2304 | I10: 2320.69 | J10: 3350 | K10: 1976.8 | L10: 25,64,322 | M10: 5,95,10,09,095.30 | N10: 1,12,846 | P10: =(H10/H9)-1 -> 0.014977974 | T10: =SLOPE(P8:P19,TECHM!R66:R77) -> 1.1666142
A11: 46268 | B11: EQ | C11: 2353.6 | D11: 2353.6 | E11: 2316.1 | F11: 2348 | G11: 2320.1 | H11: 2320.1 | I11: 2332.39 | J11: 3350 | K11: 1976.8 | L11: 18,92,786 | M11: 4,41,47,10,140.10 | N11: 90065 | P11: =(H11/H10)-1 -> 0.0069878472
A12: 46267 | B12: EQ | C12: 2347.9 | D12: 2363 | E12: 2303.5 | F12: 2369 | G12: 2348 | H12: 2348 | I12: 2338.28 | J12: 3350 | K12: 1976.8 | L12: 25,33,005 | M12: 5,92,28,81,120.10 | N12: 96240 | P12: =(H12/H11)-1 -> 0.012025344
A13: 46266 | B13: EQ | C13: 2355 | D13: 2372 | E13: 2325 | F13: 2399.3 | G13: 2369 | H13: 2369 | I13: 2354.15 | J13: 3350 | K13: 1976.8 | L13: 26,78,034 | M13: 6,30,44,99,313.40 | N13: 84239 | P13: =(H13/H12)-1 -> 0.0089437819
A14: 46265 | B14: EQ | C14: 2342 | D14: 2399.3 | E14: 2306.2 | F14: 2342 | G14: 2399.3 | H14: 2399.3 | I14: 2355.43 | J14: 3350 | K14: 1976.8 | L14: 29,05,846 | M14: 6,84,45,16,701.50 | N14: 69557 | P14: =(H14/H13)-1 -> 0.012790207
A15: 46262 | B15: EQ | C15: 2272 | D15: 2348.5 | E15: 2263.3 | F15: 2248.4 | G15: 2342 | H15: 2342 | I15: 2327.97 | J15: 3350 | K15: 1976.8 | L15: 40,54,069 | M15: 9,43,77,54,087.90 | N15: 1,55,502 | P15: =(H15/H14)-1 -> -0.023881966
A16: 46261 | B16: EQ | C16: 2270 | D16: 2283.6 | E16: 2243.9 | F16: 2270 | G16: 2248.4 | H16: 2248.4 | I16: 2255.48 | J16: 3350 | K16: 1976.8 | L16: 17,09,113 | M16: 3,85,48,63,391.00 | N16: 1,31,520 | P16: =(H16/H15)-1 -> -0.039965841
A17: 46260 | B17: EQ | C17: 2305.1 | D17: 2306.3 | E17: 2266.4 | F17: 2296.2 | G17: 2270 | H17: 2270 | I17: 2277.39 | J17: 3350 | K17: 1976.8 | L17: 16,60,737 | M17: 3,78,21,46,389.70 | N17: 59558 | P17: =(H17/H16)-1 -> 0.0096068315
A18: 46259 | B18: EQ | C18: 2305 | D18: 2313.5 | E18: 2262 | F18: 2284.1 | G18: 2296.2 | H18: 2296.2 | I18: 2283.22 | J18: 3350 | K18: 1976.8 | L18: 30,41,609 | M18: 6,94,46,64,134.30 | N18: 1,06,591 | P18: =(H18/H17)-1 -> 0.01154185
A19: 46258 | B19: EQ | C19: 2302.4 | D19: 2321.6 | E19: 2279.5 | F19: 2302 | G19: 2284.1 | H19: 2284.1 | I19: 2295.75 | J19: 3350 | K19: 1976.8 | L19: 15,42,723 | M19: 3,54,17,10,701.30 | N19: 64928 | P19: =(H19/H18)-1 -> -0.0052695758

Sheet Wipro
O1: DATA FROM NSE
E2: HISTORICAL DATA WIPRO
A3: DATE | B3: SERIES | C3: OPEN | D3: HIGH | E3: LOW | F3: PREV. CLOSE | G3: LTP | H3: CLOSE | I3: VWAP | J3: 52 WEEK HIGH | K3: 52 WEEK LOW | L3: VOLUME | M3: VALUE | N3: NO. OF TRADES | P3: DAILY % RETURNS | Q3: Standard Deviation | R3: Average of DR | S3: Cumulative Returns | T3: Beta Coefficient
A4: 46276 | B4: EQ | C4: 165.2 | D4: 167.75 | E4: 165.16 | F4: 166.3 | G4: 167.4 | H4: 167.4 | I4: 166.93 | J4: 273.1 | K4: 165.16 | L4: 84,84,897 | M4: 1,41,64,05,057.35 | N4: 69199 | P4: 0 | T4: SEP
A5: 46275 | B5: EQ | C5: 167.9 | D5: 169.19 | E5: 166 | F5: 167 | G5: 166.3 | H5: 166.3 | I5: 166.97 | J5: 273.1 | K5: 166 | L5: 95,86,645 | M5: 1,60,06,78,806.38 | N5: 77695 | P5: =(H5/H4)-1 -> -0.0065710872 | Q5: =_xlfn.STDEV.S(P5:P18) -> 0.015466276 | R5: =AVERAGE(P5:P18) -> 0.0058289057 | S5: =(H18-H4)/H4 -> 0.083094385 | T5: =SLOPE(P5:P18,TECHM!R30:R43) -> 0.12673389
A6: 46274 | B6: EQ | C6: 168.7 | D6: 169.15 | E6: 166.37 | F6: 171.5 | G6: 167 | H6: 167 | I6: 167.71 | J6: 273.1 | K6: 166.37 | L6: 1,20,01,620 | M6: 2,01,28,30,925.32 | N6: 1,17,652 | P6: =(H6/H5)-1 -> 0.0042092604 | T6: OCT
A7: 46273 | B7: EQ | C7: 172.8 | D7: 172.9 | E7: 171.13 | F7: 172.8 | G7: 171.5 | H7: 171.5 | I7: 171.73 | J7: 273.1 | K7: 169 | L7: 69,48,945 | M7: 1,19,33,26,130.04 | N7: 70344 | P7: =(H7/H6)-1 -> 0.026946108 | T7: =SLOPE(P5:P18,TECHM!R47:R60) -> 0.29182439
A8: 46272 | B8: EQ | C8: 175.89 | D8: 176.47 | E8: 172.65 | F8: 176.4 | G8: 172.8 | H8: 172.8 | I8: 173.62 | J8: 273.1 | K8: 169 | L8: 1,07,20,636 | M8: 1,86,13,27,806.30 | N8: 1,04,981 | P8: =(H8/H7)-1 -> 0.0075801749 | T8: NOV
A9: 46269 | B9: EQ | C9: 176.74 | D9: 178.75 | E9: 176.4 | F9: 175.72 | G9: 176.4 | H9: 176.4 | I9: 177.62 | J9: 273.1 | K9: 169 | L9: 68,82,678 | M9: 1,22,25,02,362.77 | N9: 48742 | P9: =(H9/H8)-1 -> 0.020833333 | T9: =SLOPE(P7:P18,TECHM!R65:R76) -> 0.17741709
A10: 46268 | B10: EQ | C10: 177.5 | D10: 178.04 | E10: 175.72 | F10: 177.09 | G10: 175.72 | H10: 175.72 | I10: 176.91 | J10: 273.1 | K10: 169 | L10: 64,96,396 | M10: 1,14,92,63,457.98 | N10: 52799 | P10: =(H10/H9)-1 -> -0.0038548753
A11: 46267 | B11: EQ | C11: 180 | D11: 180.39 | E11: 176.8 | F11: 181.7 | G11: 177.09 | H11: 177.09 | I11: 177.85 | J11: 273.1 | K11: 169 | L11: 1,20,56,634 | M11: 2,14,42,79,105.16 | N11: 1,01,352 | P11: =(H11/H10)-1 -> 0.0077964944
A12: 46266 | B12: EQ | C12: 181 | D12: 182.1 | E12: 178.5 | F12: 184.5 | G12: 181.7 | H12: 181.7 | I12: 181.02 | J12: 273.1 | K12: 169 | L12: 68,13,425 | M12: 1,23,33,78,820.04 | N12: 58669 | P12: =(H12/H11)-1 -> 0.026031961
A13: 46265 | B13: EQ | C13: 180.17 | D13: 184.5 | E13: 176.17 | F13: 180.95 | G13: 184.5 | H13: 184.5 | I13: 180.81 | J13: 273.1 | K13: 169 | L13: 1,66,66,567 | M13: 3,01,35,41,281.24 | N13: 74522 | P13: =(H13/H12)-1 -> 0.015410017
A14: 46262 | B14: EQ | C14: 178.25 | D14: 181.85 | E14: 178.25 | F14: 176.4 | G14: 180.95 | H14: 180.95 | I14: 180.28 | J14: 273.1 | K14: 169 | L14: 1,46,86,269 | M14: 2,64,76,12,449.73 | N14: 78138 | P14: =(H14/H13)-1 -> -0.019241192
A15: 46261 | B15: EQ | C15: 177.35 | D15: 178.7 | E15: 176.4 | F15: 177.35 | G15: 176.4 | H15: 176.4 | I15: 177.35 | J15: 273.1 | K15: 169 | L15: 46,95,019 | M15: 83,26,39,252.33 | N15: 54303 | P15: =(H15/H14)-1 -> -0.025145068
A16: 46260 | B16: EQ | C16: 180.09 | D16: 180.95 | E16: 176.66 | F16: 180.09 | G16: 177.35 | H16: 177.35 | I16: 178.27 | J16: 273.1 | K16: 169 | L16: 93,55,776 | M16: 1,66,78,99,694.74 | N16: 67256 | P16: =(H16/H15)-1 -> 0.0053854875
A17: 46259 | B17: EQ | C17: 181.29 | D17: 181.29 | E17: 178.39 | F17: 181.31 | G17: 180.09 | H17: 180.09 | I17: 179.67 | J17: 273.1 | K17: 169 | L17: 83,52,475 | M17: 1,50,06,60,143.63 | N17: 61275 | P17: =(H17/H16)-1 -> 0.015449676
A18: 46258 | B18: EQ | C18: 181 | D18: 183.92 | E18: 180.56 | F18: 180.79 | G18: 181.31 | H18: 181.31 | I18: 181.96 | J18: 273.1 | K18: 169 | L18: 94,41,129 | M18: 1,71,79,16,986.71 | N18: 83122 | P18: =(H18/H17)-1 -> 0.0067743906

Sheet Infosys
T1: DATA FROM NSE
E2: HISTORICAL DATA INFOSYS
A3: DATE | B3: SERIES | C3: OPEN | D3: HIGH | E3: LOW | F3: PREV. CLOSE | G3: LTP | H3: CLOSE | I3: VWAP | J3: 52 WEEK HIGH | K3: 52 WEEK LOW | L3: VOLUME | M3: VALUE | N3: NO. OF TRADES | P3: DAILY % RETURNS | Q3: Standard Deviation | R3: Average of DR | S3: Cumulative Returns | T3: Beta Coefficient
A4: 46276 | B4: EQ | C4: 1032 | D4: 1047.3 | E4: 1029.7 | F4: 1036.5 | G4: 1037.7 | H4: 1037.7 | I4: 1039.69 | J4: 1728 | K4: 982.4 | L4: 61,68,088 | M4: 6,41,29,29,953.10 | N4: 1,45,206 | P4: 0 | T4: SEP
A5: 46275 | B5: EQ | C5: 1039.6 | D5: 1046.6 | E5: 1027.3 | F5: 1035 | G5: 1036.5 | H5: 1036.5 | I5: 1035.09 | J5: 1728 | K5: 982.4 | L5: 89,98,529 | M5: 9,31,42,45,718.70 | N5: 1,32,817 | P5: =(H5/H4)-1 -> -0.0011564036 | Q5: =_xlfn.STDEV.S(P5:P18) -> 0.020199972 | R5: =AVERAGE(P5:P18) -> 0.0062926675 | S5: =(H18-H4)/H4 -> 0.088946709 | T5: =SLOPE(P5:P18,TECHM!R30:R43) -> 0.61173236
A6: 46274 | B6: EQ | C6: 1059 | D6: 1059 | E6: 1026.5 | F6: 1082 | G6: 1035 | H6: 1035 | I6: 1038.28 | J6: 1728 | K6: 982.4 | L6: 1,35,30,457 | M6: 14,04,83,85,874.80 | N6: 2,48,758 | P6: =(H6/H5)-1 -> -0.001447178 | T6: OCT
A7: 46273 | B7: EQ | C7: 1095 | D7: 1095 | E7: 1078.9 | F7: 1087.5 | G7: 1082 | H7: 1082 | I7: 1084.29 | J7: 1728 | K7: 982.4 | L7: 62,69,037 | M7: 6,79,74,33,881.60 | N7: 1,51,673 | P7: =(H7/H6)-1 -> 0.045410628 | T7: =SLOPE(P5:P18,TECHM!R47:R60) -> 0.75295644
A8: 46272 | B8: EQ | C8: 1109.5 | D8: 1109.9 | E8: 1085 | F8: 1130 | G8: 1087.5 | H8: 1087.5 | I8: 1094.17 | J8: 1728 | K8: 982.4 | L8: 76,68,346 | M8: 8,39,04,99,184.00 | N8: 1,95,551 | P8: =(H8/H7)-1 -> 0.0050831793 | T8: NOV
A9: 46269 | B9: EQ | C9: 1133 | D9: 1146.7 | E9: 1125.4 | F9: 1130.3 | G9: 1130 | H9: 1130 | I9: 1132.09 | J9: 1728 | K9: 982.4 | L9: 58,81,388 | M9: 6,65,82,77,427.90 | N9: 1,09,162 | P9: =(H9/H8)-1 -> 0.03908046 | T9: =SLOPE(P7:P18,TECHM!R65:R76) -> 1.1662689
A10: 46268 | B10: EQ | C10: 1144 | D10: 1144 | E10: 1122.5 | F10: 1140 | G10: 1130.3 | H10: 1130.3 | I10: 1130.6 | J10: 1728 | K10: 982.4 | L10: 57,86,250 | M10: 6,54,19,60,761.60 | N10: 1,72,536 | P10: =(H10/H9)-1 -> 0.00026548673
A11: 46267 | B11: EQ | C11: 1137.7 | D11: 1147.8 | E11: 1118.6 | F11: 1156 | G11: 1140 | H11: 1140 | I11: 1134.99 | J11: 1728 | K11: 982.4 | L11: 85,64,358 | M11: 9,72,05,00,603.10 | N11: 1,92,466 | P11: =(H11/H10)-1 -> 0.0085817924
A12: 46266 | B12: EQ | C12: 1128 | D12: 1156 | E12: 1125.6 | F12: 1133.8 | G12: 1156 | H12: 1156 | I12: 1145.4 | J12: 1728 | K12: 982.4 | L12: 1,35,16,123 | M12: 15,48,13,78,653.40 | N12: 1,63,276 | P12: =(H12/H11)-1 -> 0.014035088
A13: 46265 | B13: EQ | C13: 1138.6 | D13: 1143.9 | E13: 1111.1 | F13: 1144 | G13: 1133.8 | H13: 1133.8 | I13: 1125.02 | J13: 1728 | K13: 982.4 | L13: 88,08,120 | M13: 9,90,93,13,175.80 | N13: 1,18,949 | P13: =(H13/H12)-1 -> -0.019204152
A14: 46262 | B14: EQ | C14: 1123.6 | D14: 1145 | E14: 1123.3 | F14: 1110.8 | G14: 1144 | H14: 1144 | I14: 1139.38 | J14: 1728 | K14: 982.4 | L14: 96,21,969 | M14: 10,96,30,88,036.20 | N14: 1,47,819 | P14: =(H14/H13)-1 -> 0.0089962956
A15: 46261 | B15: EQ | C15: 1120 | D15: 1130.7 | E15: 1107.2 | F15: 1120 | G15: 1110.8 | H15: 1110.8 | I15: 1112.52 | J15: 1728 | K15: 982.4 | L15: 69,33,998 | M15: 7,71,41,83,978.30 | N15: 1,32,760 | P15: =(H15/H14)-1 -> -0.029020979
A16: 46260 | B16: EQ | C16: 1142 | D16: 1142 | E16: 1118.3 | F16: 1144 | G16: 1120 | H16: 1120 | I16: 1125.69 | J16: 1728 | K16: 982.4 | L16: 63,23,984 | M16: 7,11,88,76,913.10 | N16: 88562 | P16: =(H16/H15)-1 -> 0.008282319
A17: 46259 | B17: EQ | C17: 1132 | D17: 1144 | E17: 1119.9 | F17: 1130 | G17: 1144 | H17: 1144 | I17: 1126.97 | J17: 1728 | K17: 982.4 | L17: 81,21,237 | M17: 9,15,23,54,371.60 | N17: 1,30,691 | P17: =(H17/H16)-1 -> 0.021428571
A18: 46258 | B18: EQ | C18: 1126.5 | D18: 1144.5 | E18: 1122 | F18: 1121 | G18: 1130 | H18: 1130 | I18: 1133.16 | J18: 1728 | K18: 982.4 | L18: 85,65,354 | M18: 9,70,59,45,957.70 | N18: 1,70,563 | P18: =(H18/H17)-1 -> -0.012237762

Sheet analysis
B2: Standard Deviation | C2: Average of DR | D2: Cumulative Returns | E2: Beta Coefficient
A3: TECH MAHINDRA | B3: =TECHM!R9 -> 0.016644223 | C3: =TECHM!S9 -> 0.0019657047 | D3: =TECHM!T9 -> 0.027903958 | E3: =TECHM!U9 -> -0.81398852
A4: TCS | B4: =TCS!Q6 -> 0.01636905 | C4: =TCS!R6 -> 0.0027833391 | D4: =TCS!S6 -> 0.037849873 | E4: =TCS!T6 -> 0.57311927
A5: WIPRO | B5: =Wipro!Q5 -> 0.015466276 | C5: =Wipro!R5 -> 0.0058289057 | D5: =Wipro!S5 -> 0.083094385 | E5: =Wipro!T5 -> 0.12673389
A6: INFOSYS | B6: =Infosys!Q5 -> 0.020199972 | C6: =Infosys!R5 -> 0.0062926675 | D6: =Infosys!S5 -> 0.088946709 | E6: =Infosys!T5 -> 0.61173236
F11: =TECHM!V17 -> 0
